ProgrammingError
sqlalchemy.exc.ProgrammingError: (psycopg2.errors.UndefinedTable) relation "users" does not exist
LINE 2: FROM users 
             ^

[SQL: SELECT users.id AS users_id, users.email AS users_email, users.encrypted_password AS users_encrypted_password, users.first_name AS users_first_name, users.last_name AS users_last_name, users.time_zone AS users_time_zone, users.created_at AS users_created_at, users.updated_at AS users_updated_at 
FROM users 
WHERE users.id = %(pk_1)s]
[parameters: {'pk_1': 1}]
(Background on this error at: https://sqlalche.me/e/20/f405)

Traceback (most recent call last)
File "/home/runner/Gorilla-Tasks/.pythonlibs/lib/python3.11/site-packages/sqlalchemy/engine/base.py", line 1967, in _exec_single_context
self.dialect.do_execute(
^
File "/home/runner/Gorilla-Tasks/.pythonlibs/lib/python3.11/site-packages/sqlalchemy/engine/default.py", line 941, in do_execute
cursor.execute(statement, parameters)
^^^^^^^^^^^^^^^^^^^^^^^^^^^^^^^^^^^^^
The above exception was the direct cause of the following exception:
File "/home/runner/Gorilla-Tasks/.pythonlibs/lib/python3.11/site-packages/flask/app.py", line 1514, in wsgi_app
response = self.handle_exception(e)
           ^^^^^^^^^^^^^^^^^^^^^^^^
File "/home/runner/Gorilla-Tasks/.pythonlibs/lib/python3.11/site-packages/flask/app.py", line 1511, in wsgi_app
response = self.full_dispatch_request()
           ^^^^^^^^^^^^^^^^^^^^^^^^^^^^
File "/home/runner/Gorilla-Tasks/.pythonlibs/lib/python3.11/site-packages/flask/app.py", line 919, in full_dispatch_request
rv = self.handle_user_exception(e)
     ^^^^^^^^^^^^^^^^^^^^^^^^^^^^^
File "/home/runner/Gorilla-Tasks/.pythonlibs/lib/python3.11/site-packages/flask/app.py", line 917, in full_dispatch_request
rv = self.dispatch_request()
     ^^^^^^^^^^^^^^^^^^^^^^^
File "/home/runner/Gorilla-Tasks/.pythonlibs/lib/python3.11/site-packages/flask/app.py", line 902, in dispatch_request
return self.ensure_sync(self.view_functions[rule.endpoint])(**view_args)  # type: ignore[no-any-return]
       ^^^^^^^^^^^^^^^^^^^^^^^^^^^^^^^^^^^^^^^^^^^^^^^^^^^^^^^^^^^^^^^^^
File "/home/runner/Gorilla-Tasks/routes.py", line 44, in login
if current_user.is_authenticated:
   ^^^^^^^^^^^^^^^^^^^^^^^^^^^^^
File "/home/runner/Gorilla-Tasks/.pythonlibs/lib/python3.11/site-packages/werkzeug/local.py", line 318, in __get__
obj = instance._get_current_object()
      ^^^^^^^^^^^^^^^^^^^^^^^^^^^^^^
File "/home/runner/Gorilla-Tasks/.pythonlibs/lib/python3.11/site-packages/werkzeug/local.py", line 526, in _get_current_object
return get_name(local())
                ^^^^^^^
File "/home/runner/Gorilla-Tasks/.pythonlibs/lib/python3.11/site-packages/flask_login/utils.py", line 25, in <lambda>
current_user = LocalProxy(lambda: _get_user())
                                  ^^^^^^^^^^^
File "/home/runner/Gorilla-Tasks/.pythonlibs/lib/python3.11/site-packages/flask_login/utils.py", line 370, in _get_user
current_app.login_manager._load_user()
^^^^^^^^^^^^^^^^^^^^^^^^^^^^^^^^^^^^^^
File "/home/runner/Gorilla-Tasks/.pythonlibs/lib/python3.11/site-packages/flask_login/login_manager.py", line 364, in _load_user
user = self._user_callback(user_id)
       ^^^^^^^^^^^^^^^^^^^^^^^^^^^^
File "/home/runner/Gorilla-Tasks/models.py", line 10, in load_user
return User.query.get(int(user_id))
       ^^^^^^^^^^^^^^^^^^^^^^^^^^^^
File "<string>", line 2, in get
File "/home/runner/Gorilla-Tasks/.pythonlibs/lib/python3.11/site-packages/sqlalchemy/util/deprecations.py", line 386, in warned
return fn(*args, **kwargs)  # type: ignore[no-any-return]
       ^^^^^^^^^^^^^^^^^^^
File "/home/runner/Gorilla-Tasks/.pythonlibs/lib/python3.11/site-packages/sqlalchemy/orm/query.py", line 1127, in get
return self._get_impl(ident, loading.load_on_pk_identity)
       ^^^^^^^^^^^^^^^^^^^^^^^^^^^^^^^^^^^^^^^^^^^^^^^^^^
File "/home/runner/Gorilla-Tasks/.pythonlibs/lib/python3.11/site-packages/sqlalchemy/orm/query.py", line 1136, in _get_impl
return self.session._get_impl(
       
File "/home/runner/Gorilla-Tasks/.pythonlibs/lib/python3.11/site-packages/sqlalchemy/orm/session.py", line 3873, in _get_impl
return db_load_fn(
       
File "/home/runner/Gorilla-Tasks/.pythonlibs/lib/python3.11/site-packages/sqlalchemy/orm/loading.py", line 694, in load_on_pk_identity
session.execute(
^
File "/home/runner/Gorilla-Tasks/.pythonlibs/lib/python3.11/site-packages/sqlalchemy/orm/session.py", line 2362, in execute
return self._execute_internal(
       
File "/home/runner/Gorilla-Tasks/.pythonlibs/lib/python3.11/site-packages/sqlalchemy/orm/session.py", line 2247, in _execute_internal
result: Result[Any] = compile_state_cls.orm_execute_statement(
                      
File "/home/runner/Gorilla-Tasks/.pythonlibs/lib/python3.11/site-packages/sqlalchemy/orm/context.py", line 305, in orm_execute_statement
result = conn.execute(
         
File "/home/runner/Gorilla-Tasks/.pythonlibs/lib/python3.11/site-packages/sqlalchemy/engine/base.py", line 1418, in execute
return meth(
       
File "/home/runner/Gorilla-Tasks/.pythonlibs/lib/python3.11/site-packages/sqlalchemy/sql/elements.py", line 515, in _execute_on_connection
return connection._execute_clauseelement(
       
File "/home/runner/Gorilla-Tasks/.pythonlibs/lib/python3.11/site-packages/sqlalchemy/engine/base.py", line 1640, in _execute_clauseelement
ret = self._execute_context(
      
File "/home/runner/Gorilla-Tasks/.pythonlibs/lib/python3.11/site-packages/sqlalchemy/engine/base.py", line 1846, in _execute_context
return self._exec_single_context(
       
File "/home/runner/Gorilla-Tasks/.pythonlibs/lib/python3.11/site-packages/sqlalchemy/engine/base.py", line 1986, in _exec_single_context
self._handle_dbapi_exception(
^
File "/home/runner/Gorilla-Tasks/.pythonlibs/lib/python3.11/site-packages/sqlalchemy/engine/base.py", line 2355, in _handle_dbapi_exception
raise sqlalchemy_exception.with_traceback(exc_info[2]) from e
^^^^^^^^^^^^^^^^^^^^^^^^^^^^^^^^^^^^^^^^^^^^^^^^^^^^^^^^^^^^^
File "/home/runner/Gorilla-Tasks/.pythonlibs/lib/python3.11/site-packages/sqlalchemy/engine/base.py", line 1967, in _exec_single_context
self.dialect.do_execute(
^
File "/home/runner/Gorilla-Tasks/.pythonlibs/lib/python3.11/site-packages/sqlalchemy/engine/default.py", line 941, in do_execute
cursor.execute(statement, parameters)
^^^^^^^^^^^^^^^^^^^^^^^^^^^^^^^^^^^^^
sqlalchemy.exc.ProgrammingError: (psycopg2.errors.UndefinedTable) relation "users" does not exist
LINE 2: FROM users
^

[SQL: SELECT users.id AS users_id, users.email AS users_email, users.encrypted_password AS users_encrypted_password, users.first_name AS users_first_name, users.last_name AS users_last_name, users.time_zone AS users_time_zone, users.created_at AS users_created_at, users.updated_at AS users_updated_at
FROM users
WHERE users.id = %(pk_1)s]
[parameters: {'pk_1': 1}]
(Background on this error at: https://sqlalche.me/e/20/f405)
The debugger caught an exception in your WSGI application. You can now look at the traceback which led to the error.
To switch between the interactive traceback and the plaintext one, you can click on the "Traceback" headline. From the text traceback you can also create a paste of it.