UndefinedError
jinja2.exceptions.UndefinedError: 'models.Enrollment object' has no attribute 'tasks_completed_today'

Traceback (most recent call last)
File "/home/runner/Gorilla-Tasks/.pythonlibs/lib/python3.11/site-packages/flask/app.py", line 1514, in wsgi_app
response = self.handle_exception(e)
           ^^^^^^^^^^^^^^^^^^^^^^^^
File "/home/runner/Gorilla-Tasks/.pythonlibs/lib/python3.11/site-packages/flask/app.py", line 1511, in wsgi_app
response = self.full_dispatch_request()
           ^^^^^^^^^^^^^^^^^^^^^^^^^^^^
File "/home/runner/Gorilla-Tasks/.pythonlibs/lib/python3.11/site-packages/flask/app.py", line 919, in full_dispatch_request
rv = self.handle_user_exception(e)
     ^^^^^^^^^^^^^^^^^^^^^^^^^^^^^
File "/home/runner/Gorilla-Tasks/.pythonlibs/lib/python3.11/site-packages/flask/app.py", line 917, in full_dispatch_request
rv = self.dispatch_request()
     ^^^^^^^^^^^^^^^^^^^^^^^
File "/home/runner/Gorilla-Tasks/.pythonlibs/lib/python3.11/site-packages/flask/app.py", line 902, in dispatch_request
return self.ensure_sync(self.view_functions[rule.endpoint])(**view_args)  # type: ignore[no-any-return]
       ^^^^^^^^^^^^^^^^^^^^^^^^^^^^^^^^^^^^^^^^^^^^^^^^^^^^^^^^^^^^^^^^^
File "/home/runner/Gorilla-Tasks/.pythonlibs/lib/python3.11/site-packages/flask_login/utils.py", line 290, in decorated_view
return current_app.ensure_sync(func)(*args, **kwargs)
       ^^^^^^^^^^^^^^^^^^^^^^^^^^^^^^^^^^^^^^^^^^^^^^
File "/home/runner/Gorilla-Tasks/routes.py", line 121, in index
return render_template('dashboard/index.html',
       ^^^^^^^^^^^^^^^^^^^^^^^^^^^^^^^^^^^^^^^^
File "/home/runner/Gorilla-Tasks/.pythonlibs/lib/python3.11/site-packages/flask/templating.py", line 150, in render_template
return _render(app, template, context)
       ^^^^^^^^^^^^^^^^^^^^^^^^^^^^^^^
File "/home/runner/Gorilla-Tasks/.pythonlibs/lib/python3.11/site-packages/flask/templating.py", line 131, in _render
rv = template.render(context)
     ^^^^^^^^^^^^^^^^^^^^^^^^
File "/home/runner/Gorilla-Tasks/.pythonlibs/lib/python3.11/site-packages/jinja2/environment.py", line 1304, in render
self.environment.handle_exception()
^^^^^^^^^^^^^^^^^^^^^^^^^^^^^^^^^^^
File "/home/runner/Gorilla-Tasks/.pythonlibs/lib/python3.11/site-packages/jinja2/environment.py", line 939, in handle_exception
raise rewrite_traceback_stack(source=source)
^^^^^^^^^^^^^^^^^^^^^^^^^^^^^^^^^^^^^^^^^^^^
File "/home/runner/Gorilla-Tasks/templates/dashboard/index.html", line 14, in top-level template code
{% extends "base.html" %}
File "/home/runner/Gorilla-Tasks/templates/base.html", line 59, in top-level template code
{% block content %}{% endblock %}
File "/home/runner/Gorilla-Tasks/templates/dashboard/index.html", line 215, in block 'content'
<span class="{{ enrollment.progress_status(enrollment.tasks_completed_today(), enrollment.calculate_todays_goal()) }}">
File "/home/runner/Gorilla-Tasks/.pythonlibs/lib/python3.11/site-packages/jinja2/utils.py", line 83, in from_obj
if hasattr(obj, "jinja_pass_arg"):
   ^^^^^^^^^^^^^^^^^^^^^^^^^^^^^^
jinja2.exceptions.UndefinedError: 'models.Enrollment object' has no attribute 'tasks_completed_today'
The debugger caught an exception in your WSGI application. You can now look at the traceback which led to the error.
To switch between the interactive traceback and the plaintext one, you can click on the "Traceback" headline. From the text traceback you can also create a paste of it.