/home/runner/workspace/migrate_encrypted_passwords.py:33: LegacyAPIWarning: The Query.get() method is considered legacy as of the 1.x series of SQLAlchemy and becomes a legacy construct in 2.0. The method is now available as Session.get() (deprecated since: 2.0) (Background on SQLAlchemy 2.0 at: https://sqlalche.me/e/b8d9)
  user = User.query.get(user_id)
2025-03-08 23:11:49,524 - __main__ - INFO - Migrating password for user 1 (phoebezcole@gmail.com)
2025-03-08 23:11:49,525 - __main__ - INFO - Migrating password for user 3 (stellanovacole@gmail.com)
2025-03-08 23:11:49,525 - __main__ - INFO - Migrating password for user 4 (felixtiptoncole@gmail.com)
2025-03-08 23:11:49,525 - __main__ - INFO - Migrating password for user 5 (emily.juergens@gmail.com)
2025-03-08 23:11:49,525 - __main__ - INFO - Migrating password for user 6 (orion.bull@icloud.com)
2025-03-08 23:11:49,525 - __main__ - INFO - Migrating password for user 7 (macy.bull12@gmail.com)
2025-03-08 23:11:49,525 - __main__ - INFO - Migrating password for user 8 (saeus.bull@yahoo.com)
2025-03-08 23:11:49,525 - __main__ - INFO - Migrating password for user 9 (entertainment)
2025-03-08 23:11:49,525 - __main__ - INFO - Migrating password for user 2 (sallycole@gmail.com)
2025-03-08 23:11:49,526 - __main__ - INFO - Migrating password for user 10 (AyresAveryAcademy)
2025-03-08 23:11:49,526 - __main__ - INFO - Migrating password for user 11 (Heidi)
2025-03-08 23:11:49,526 - __main__ - INFO - Migrating password for user 12 (lkhaver@gmail.com)
Traceback (most recent call last):
  File "/home/runner/workspace/.pythonlibs/lib/python3.11/site-packages/sqlalchemy/engine/base.py", line 1936, in _exec_single_context
    self.dialect.do_executemany(
  File "/home/runner/workspace/.pythonlibs/lib/python3.11/site-packages/sqlalchemy/dialects/postgresql/psycopg2.py", line 794, in do_executemany
    cursor.executemany(statement, parameters)
psycopg2.errors.StringDataRightTruncation: value too long for type character varying(128)


The above exception was the direct cause of the following exception:

Traceback (most recent call last):
  File "/home/runner/workspace/migrate_encrypted_passwords.py", line 60, in <module>
    migrate_encrypted_passwords()
  File "/home/runner/workspace/migrate_encrypted_passwords.py", line 52, in migrate_encrypted_passwords
    db.session.commit()
  File "/home/runner/workspace/.pythonlibs/lib/python3.11/site-packages/sqlalchemy/orm/scoping.py", line 597, in commit
    return self._proxied.commit()
           ^^^^^^^^^^^^^^^^^^^^^^
  File "/home/runner/workspace/.pythonlibs/lib/python3.11/site-packages/sqlalchemy/orm/session.py", line 2028, in commit
    trans.commit(_to_root=True)
  File "<string>", line 2, in commit
  File "/home/runner/workspace/.pythonlibs/lib/python3.11/site-packages/sqlalchemy/orm/state_changes.py", line 139, in _go
    ret_value = fn(self, *arg, **kw)
                ^^^^^^^^^^^^^^^^^^^^
  File "/home/runner/workspace/.pythonlibs/lib/python3.11/site-packages/sqlalchemy/orm/session.py", line 1313, in commit
    self._prepare_impl()
  File "<string>", line 2, in _prepare_impl
  File "/home/runner/workspace/.pythonlibs/lib/python3.11/site-packages/sqlalchemy/orm/state_changes.py", line 139, in _go
    ret_value = fn(self, *arg, **kw)
                ^^^^^^^^^^^^^^^^^^^^
  File "/home/runner/workspace/.pythonlibs/lib/python3.11/site-packages/sqlalchemy/orm/session.py", line 1288, in _prepare_impl
    self.session.flush()
  File "/home/runner/workspace/.pythonlibs/lib/python3.11/site-packages/sqlalchemy/orm/session.py", line 4352, in flush
    self._flush(objects)
  File "/home/runner/workspace/.pythonlibs/lib/python3.11/site-packages/sqlalchemy/orm/session.py", line 4487, in _flush
    with util.safe_reraise():
  File "/home/runner/workspace/.pythonlibs/lib/python3.11/site-packages/sqlalchemy/util/langhelpers.py", line 146, in __exit__
    raise exc_value.with_traceback(exc_tb)
  File "/home/runner/workspace/.pythonlibs/lib/python3.11/site-packages/sqlalchemy/orm/session.py", line 4448, in _flush
    flush_context.execute()
  File "/home/runner/workspace/.pythonlibs/lib/python3.11/site-packages/sqlalchemy/orm/unitofwork.py", line 466, in execute
    rec.execute(self)
  File "/home/runner/workspace/.pythonlibs/lib/python3.11/site-packages/sqlalchemy/orm/unitofwork.py", line 642, in execute
    util.preloaded.orm_persistence.save_obj(
  File "/home/runner/workspace/.pythonlibs/lib/python3.11/site-packages/sqlalchemy/orm/persistence.py", line 85, in save_obj
    _emit_update_statements(
  File "/home/runner/workspace/.pythonlibs/lib/python3.11/site-packages/sqlalchemy/orm/persistence.py", line 912, in _emit_update_statements
    c = connection.execute(
        ^^^^^^^^^^^^^^^^^^^
  File "/home/runner/workspace/.pythonlibs/lib/python3.11/site-packages/sqlalchemy/engine/base.py", line 1418, in execute
    return meth(
           ^^^^^
  File "/home/runner/workspace/.pythonlibs/lib/python3.11/site-packages/sqlalchemy/sql/elements.py", line 515, in _execute_on_connection
    return connection._execute_clauseelement(
           ^^^^^^^^^^^^^^^^^^^^^^^^^^^^^^^^^^
  File "/home/runner/workspace/.pythonlibs/lib/python3.11/site-packages/sqlalchemy/engine/base.py", line 1640, in _execute_clauseelement
    ret = self._execute_context(
          ^^^^^^^^^^^^^^^^^^^^^^
  File "/home/runner/workspace/.pythonlibs/lib/python3.11/site-packages/sqlalchemy/engine/base.py", line 1846, in _execute_context
    return self._exec_single_context(
           ^^^^^^^^^^^^^^^^^^^^^^^^^^
  File "/home/runner/workspace/.pythonlibs/lib/python3.11/site-packages/sqlalchemy/engine/base.py", line 1986, in _exec_single_context
    self._handle_dbapi_exception(
  File "/home/runner/workspace/.pythonlibs/lib/python3.11/site-packages/sqlalchemy/engine/base.py", line 2355, in _handle_dbapi_exception
    raise sqlalchemy_exception.with_traceback(exc_info[2]) from e
  File "/home/runner/workspace/.pythonlibs/lib/python3.11/site-packages/sqlalchemy/engine/base.py", line 1936, in _exec_single_context
    self.dialect.do_executemany(
  File "/home/runner/workspace/.pythonlibs/lib/python3.11/site-packages/sqlalchemy/dialects/postgresql/psycopg2.py", line 794, in do_executemany
    cursor.executemany(statement, parameters)
sqlalchemy.exc.DataError: (psycopg2.errors.StringDataRightTruncation) value too long for type character varying(128)

[SQL: UPDATE users SET password_hash=%(password_hash)s WHERE users.id = %(users_id)s]
[parameters: [{'password_hash': 'scrypt:32768:8:1$YNiXUdIGsspbFKaF$5cc441d264bd173c7292b14d58056264921fef76eb5e5a53717bd000c7a0ee5d8d37c4ff1ea59dccac3ec80bbc43667ec09525c58cdeecc8a5e573f4fec7e2d6', 'users_id': 1}, {'password_hash': 'scrypt:32768:8:1$fJgNRzdVK29l05jM$0789ec3f7eb93a5a79080c887925a66953283ea32a69a987a8d8c4b3b5b86175209fda8ddba28ca76eeb9c762d8011d0c14cc53391cb35ad93736ef619529557', 'users_id': 2}, {'password_hash': 'scrypt:32768:8:1$r1kho5gjXujezUi2$940db51f3bd4f537d8050eba8486cf38f52e3160e11b32ebda14cbed788508211885637493d8352baaef9409c4cd1ad62e686a213ea6ae73ab14b0d6f5827ca5', 'users_id': 3}, {'password_hash': 'scrypt:32768:8:1$H9UYe9D3BMtGvLxP$2dc70fb4046e4c39e30dd282fb1bf0e79533aa9085af6e943c5bddab13c885fa2df1282811f5de4e1eaca635e59bdd5fa026b1c202b4a47d4ec949a8c92496c2', 'users_id': 4}, {'password_hash': 'scrypt:32768:8:1$1yYZju95WRRWnmVU$36a582b1772fd54b55c07a020d7885a4280685a7cca94c977e05fae751732e69ce030f7a5ed0813d170193257b677621335c6338fdc6e70f17884cb7f9cc1ee9', 'users_id': 5}, {'password_hash': 'scrypt:32768:8:1$6d8hOzTDNsR5qeHQ$af7a905b40e4d9b57878f98b6a9392f76df965bc613e874f6b15e97b963a58d82ce377cbea52db4f1a116e7dc9424f190f676bfd9e32aa85d5f70d636831cfd9', 'users_id': 6}, {'password_hash': 'scrypt:32768:8:1$Q6VA1GpLu5V8LjH4$fb3adf3a4745a0fc444f0b5fc179ccb05fd384570ab7d9b48703667f93769c331ef0589104a6c493fb1a27295ccad98716f3e43ed651a74b96d7970b60374e32', 'users_id': 7}, {'password_hash': 'scrypt:32768:8:1$xusf9diUTK8vwDWa$cf2dea9566a6ba231289aea301dc2d8817a62ed592d7fcdbdbb1b3f41514796b6fb7ce1bcae99822c33d433361ec12588e2f9af251c90eff52acf096162b970a', 'users_id': 8}  ... displaying 10 of 12 total bound parameter sets ...  {'password_hash': 'scrypt:32768:8:1$PcB5sgtSDR4VUde1$287231cfd8a3f31c62ac31a5a01320e30315c40dbbb14fe8b3d5af33c80e2e277eb44178cef996072241a207d26107ef0dd42168f48b9bf78e76f5b626cdf6b8', 'users_id': 11}, {'password_hash': 'scrypt:32768:8:1$CbP1NKCRxEHjrM2l$a107d2c80a4d7be303650e67199793e93ee8397a9d3c9fc07b824dba67ebb3d3059a9bf817d0ccf0fc8711cb7885eaacbdd593cd75cbdae6f598a8066b31e7af', 'users_id': 12}]]
(Background on this error at: https://sqlalche.me/e/20/9h9h)