IntegrityError

sqlalchemy.exc.IntegrityError: (psycopg2.errors.NotNullViolation) null value in column "encrypted_password" of relation "users" violates not-null constraint
DETAIL:  Failing row contains (19, Eduardo, null, Eduardo, Flores, Etc/GMT+6, 2025-04-26 01:53:18.460839, null, null, f, pbkdf2:sha256:1000000$hBVgy8mUgXDJ8Jxq$3bfce372363bf0872d99b70a8..., t).

[SQL: INSERT INTO users (email, username, password_hash, first_name, last_name, is_active, created_at, is_superuser, time_zone) VALUES (%(email)s, %(username)s, %(password_hash)s, %(first_name)s, %(last_name)s, %(is_active)s, %(created_at)s, %(is_superuser)s, %(time_zone)s) RETURNING users.id]
[parameters: {'email': 'Eduardo', 'username': None, 'password_hash': 'pbkdf2:sha256:1000000$hBVgy8mUgXDJ8Jxq$3bfce372363bf0872d99b70a8a07344771891762eb744f38a5988c66618aabe7', 'first_name': 'Eduardo', 'last_name': 'Flores', 'is_active': True, 'created_at': datetime.datetime(2025, 4, 26, 1, 53, 18, 460839), 'is_superuser': False, 'time_zone': 'Etc/GMT+6'}]
(Background on this error at: https://sqlalche.me/e/20/gkpj)
Traceback (most recent call last)

    File "/home/runner/workspace/.pythonlibs/lib/python3.11/site-packages/sqlalchemy/engine/base.py", line 1967, in _exec_single_context

    self.dialect.do_execute(
    ^

    File "/home/runner/workspace/.pythonlibs/lib/python3.11/site-packages/sqlalchemy/engine/default.py", line 941, in do_execute

    cursor.execute(statement, parameters)
    ^^^^^^^^^^^^^^^^^^^^^^^^^^^^^^^^^^^^^

    The above exception was the direct cause of the following exception:
    File "/home/runner/workspace/.pythonlibs/lib/python3.11/site-packages/flask/app.py", line 1514, in wsgi_app

    response = self.handle_exception(e)
               ^^^^^^^^^^^^^^^^^^^^^^^^

    File "/home/runner/workspace/.pythonlibs/lib/python3.11/site-packages/flask/app.py", line 1511, in wsgi_app

    response = self.full_dispatch_request()
               ^^^^^^^^^^^^^^^^^^^^^^^^^^^^

    File "/home/runner/workspace/.pythonlibs/lib/python3.11/site-packages/flask/app.py", line 919, in full_dispatch_request

    rv = self.handle_user_exception(e)
         ^^^^^^^^^^^^^^^^^^^^^^^^^^^^^

    File "/home/runner/workspace/.pythonlibs/lib/python3.11/site-packages/flask/app.py", line 917, in full_dispatch_request

    rv = self.dispatch_request()
         ^^^^^^^^^^^^^^^^^^^^^^^

    File "/home/runner/workspace/.pythonlibs/lib/python3.11/site-packages/flask/app.py", line 902, in dispatch_request

    return self.ensure_sync(self.view_functions[rule.endpoint])(**view_args)  # type: ignore[no-any-return]
           ^^^^^^^^^^^^^^^^^^^^^^^^^^^^^^^^^^^^^^^^^^^^^^^^^^^^^^^^^^^^^^^^^

    File "/home/runner/workspace/routes.py", line 498, in register

    db.session.commit()
    ^^^^^^^^^^^^^^^^^^^

    File "/home/runner/workspace/.pythonlibs/lib/python3.11/site-packages/sqlalchemy/orm/scoping.py", line 597, in commit

    return self._proxied.commit()
           ^^^^^^^^^^^^^^^^^^^^^^

    File "/home/runner/workspace/.pythonlibs/lib/python3.11/site-packages/sqlalchemy/orm/session.py", line 2028, in commit

    trans.commit(_to_root=True)
    ^^^^^^^^^^^^^^^^^^^^^^^^^^^

    File "<string>", line 2, in commit
    File "/home/runner/workspace/.pythonlibs/lib/python3.11/site-packages/sqlalchemy/orm/state_changes.py", line 139, in _go

    ret_value = fn(self, *arg, **kw)
                ^^^^^^^^^^^^^^^^^^^^

    File "/home/runner/workspace/.pythonlibs/lib/python3.11/site-packages/sqlalchemy/orm/session.py", line 1313, in commit

    self._prepare_impl()
    ^^^^^^^^^^^^^^^^^^^^

    File "<string>", line 2, in _prepare_impl
    File "/home/runner/workspace/.pythonlibs/lib/python3.11/site-packages/sqlalchemy/orm/state_changes.py", line 139, in _go

    ret_value = fn(self, *arg, **kw)
                ^^^^^^^^^^^^^^^^^^^^

    File "/home/runner/workspace/.pythonlibs/lib/python3.11/site-packages/sqlalchemy/orm/session.py", line 1288, in _prepare_impl

    self.session.flush()
    ^^^^^^^^^^^^^^^^^^^^

    File "/home/runner/workspace/.pythonlibs/lib/python3.11/site-packages/sqlalchemy/orm/session.py", line 4352, in flush

    self._flush(objects)
    ^^^^^^^^^^^^^^^^^^^^

    File "/home/runner/workspace/.pythonlibs/lib/python3.11/site-packages/sqlalchemy/orm/session.py", line 4487, in _flush

    with util.safe_reraise():
    ^^^^^^^^^^^^^^^^^^^^^^^^^^^^^^^^^^^^^^^^^^^^^^^^^

    File "/home/runner/workspace/.pythonlibs/lib/python3.11/site-packages/sqlalchemy/util/langhelpers.py", line 146, in __exit__

    raise exc_value.with_traceback(exc_tb)
    ^^^^^^^^^^^^^^^^^^^^^^^^^^^^^^^^^^^^^^

    File "/home/runner/workspace/.pythonlibs/lib/python3.11/site-packages/sqlalchemy/orm/session.py", line 4448, in _flush

    flush_context.execute()
    ^^^^^^^^^^^^^^^^^^^^^^^

    File "/home/runner/workspace/.pythonlibs/lib/python3.11/site-packages/sqlalchemy/orm/unitofwork.py", line 466, in execute

    rec.execute(self)
    ^^^^^^^^^^^^^^^^^

    File "/home/runner/workspace/.pythonlibs/lib/python3.11/site-packages/sqlalchemy/orm/unitofwork.py", line 642, in execute

    util.preloaded.orm_persistence.save_obj(
    ^

    File "/home/runner/workspace/.pythonlibs/lib/python3.11/site-packages/sqlalchemy/orm/persistence.py", line 93, in save_obj

    _emit_insert_statements(
    ^

    File "/home/runner/workspace/.pythonlibs/lib/python3.11/site-packages/sqlalchemy/orm/persistence.py", line 1233, in _emit_insert_statements

    result = connection.execute(
             

    File "/home/runner/workspace/.pythonlibs/lib/python3.11/site-packages/sqlalchemy/engine/base.py", line 1418, in execute

    return meth(
           

    File "/home/runner/workspace/.pythonlibs/lib/python3.11/site-packages/sqlalchemy/sql/elements.py", line 515, in _execute_on_connection

    return connection._execute_clauseelement(
           

    File "/home/runner/workspace/.pythonlibs/lib/python3.11/site-packages/sqlalchemy/engine/base.py", line 1640, in _execute_clauseelement

    ret = self._execute_context(
          

    File "/home/runner/workspace/.pythonlibs/lib/python3.11/site-packages/sqlalchemy/engine/base.py", line 1846, in _execute_context

    return self._exec_single_context(
           

    File "/home/runner/workspace/.pythonlibs/lib/python3.11/site-packages/sqlalchemy/engine/base.py", line 1986, in _exec_single_context

    self._handle_dbapi_exception(
    ^

    File "/home/runner/workspace/.pythonlibs/lib/python3.11/site-packages/sqlalchemy/engine/base.py", line 2355, in _handle_dbapi_exception

    raise sqlalchemy_exception.with_traceback(exc_info[2]) from e
    ^^^^^^^^^^^^^^^^^^^^^^^^^^^^^^^^^^^^^^^^^^^^^^^^^^^^^^^^^^^^^

    File "/home/runner/workspace/.pythonlibs/lib/python3.11/site-packages/sqlalchemy/engine/base.py", line 1967, in _exec_single_context

    self.dialect.do_execute(
    ^

    File "/home/runner/workspace/.pythonlibs/lib/python3.11/site-packages/sqlalchemy/engine/default.py", line 941, in do_execute

    cursor.execute(statement, parameters)
    ^^^^^^^^^^^^^^^^^^^^^^^^^^^^^^^^^^^^^

    sqlalchemy.exc.IntegrityError: (psycopg2.errors.NotNullViolation) null value in column "encrypted_password" of relation "users" violates not-null constraint
    DETAIL:  Failing row contains (19, Eduardo, null, Eduardo, Flores, Etc/GMT+6, 2025-04-26 01:53:18.460839, null, null, f, pbkdf2:sha256:1000000$hBVgy8mUgXDJ8Jxq$3bfce372363bf0872d99b70a8..., t).

    [SQL: INSERT INTO users (email, username, password_hash, first_name, last_name, is_active, created_at, is_superuser, time_zone) VALUES (%(email)s, %(username)s, %(password_hash)s, %(first_name)s, %(last_name)s, %(is_active)s, %(created_at)s, %(is_superuser)s, %(time_zone)s) RETURNING users.id]
    [parameters: {'email': 'Eduardo', 'username': None, 'password_hash': 'pbkdf2:sha256:1000000$hBVgy8mUgXDJ8Jxq$3bfce372363bf0872d99b70a8a07344771891762eb744f38a5988c66618aabe7', 'first_name': 'Eduardo', 'last_name': 'Flores', 'is_active': True, 'created_at': datetime.datetime(2025, 4, 26, 1, 53, 18, 460839), 'is_superuser': False, 'time_zone': 'Etc/GMT+6'}]
    (Background on this error at: https://sqlalche.me/e/20/gkpj)

The debugger caught an exception in your WSGI application. You can now look at the traceback which led to the error.

To switch between the interactive traceback and the plaintext one, you can click on the "Traceback" headline. From the text traceback you can also create a paste of it.
