ProgrammingError
sqlalchemy.exc.ProgrammingError: (psycopg2.errors.UndefinedColumn) column users.username does not exist
LINE 1: ...users.id AS users_id, users.email AS users_email, users.user...
                                                             ^

[SQL: SELECT users.id AS users_id, users.email AS users_email, users.username AS users_username, users.encrypted_password AS users_encrypted_password, users.first_name AS users_first_name, users.last_name AS users_last_name, users.time_zone AS users_time_zone, users.created_at AS users_created_at, users.updated_at AS users_updated_at 
FROM users 
WHERE users.email = %(email_1)s OR users.username IS NOT NULL AND users.username = %(username_1)s 
 LIMIT %(param_1)s]
[parameters: {'email_1': 'phoebezcole@gmail.com', 'username_1': 'phoebezcole@gmail.com', 'param_1': 1}]
(Background on this error at: https://sqlalche.me/e/20/f405)

Traceback (most recent call last)
File "/home/runner/workspace/.pythonlibs/lib/python3.11/site-packages/sqlalchemy/engine/base.py", line 1967, in _exec_single_context
self.dialect.do_execute(
^
File "/home/runner/workspace/.pythonlibs/lib/python3.11/site-packages/sqlalchemy/engine/default.py", line 941, in do_execute
cursor.execute(statement, parameters)
^^^^^^^^^^^^^^^^^^^^^^^^^^^^^^^^^^^^^
The above exception was the direct cause of the following exception:
File "/home/runner/workspace/.pythonlibs/lib/python3.11/site-packages/flask/app.py", line 1514, in wsgi_app
response = self.handle_exception(e)
           ^^^^^^^^^^^^^^^^^^^^^^^^
File "/home/runner/workspace/.pythonlibs/lib/python3.11/site-packages/flask/app.py", line 1511, in wsgi_app
response = self.full_dispatch_request()
           ^^^^^^^^^^^^^^^^^^^^^^^^^^^^
File "/home/runner/workspace/.pythonlibs/lib/python3.11/site-packages/flask/app.py", line 919, in full_dispatch_request
rv = self.handle_user_exception(e)
     ^^^^^^^^^^^^^^^^^^^^^^^^^^^^^
File "/home/runner/workspace/.pythonlibs/lib/python3.11/site-packages/flask/app.py", line 917, in full_dispatch_request
rv = self.dispatch_request()
     ^^^^^^^^^^^^^^^^^^^^^^^
File "/home/runner/workspace/.pythonlibs/lib/python3.11/site-packages/flask/app.py", line 902, in dispatch_request
return self.ensure_sync(self.view_functions[rule.endpoint])(**view_args)  # type: ignore[no-any-return]
       ^^^^^^^^^^^^^^^^^^^^^^^^^^^^^^^^^^^^^^^^^^^^^^^^^^^^^^^^^^^^^^^^^
File "/home/runner/workspace/routes.py", line 152, in login
).first()
  ^^^^^^^
File "/home/runner/workspace/.pythonlibs/lib/python3.11/site-packages/sqlalchemy/orm/query.py", line 2728, in first
return self.limit(1)._iter().first()  # type: ignore
       ^^^^^^^^^^^^^^^^^^^^^
File "/home/runner/workspace/.pythonlibs/lib/python3.11/site-packages/sqlalchemy/orm/query.py", line 2827, in _iter
result: Union[ScalarResult[_T], Result[_T]] = self.session.execute(
                                              
File "/home/runner/workspace/.pythonlibs/lib/python3.11/site-packages/sqlalchemy/orm/session.py", line 2362, in execute
return self._execute_internal(
       
File "/home/runner/workspace/.pythonlibs/lib/python3.11/site-packages/sqlalchemy/orm/session.py", line 2247, in _execute_internal
result: Result[Any] = compile_state_cls.orm_execute_statement(
                      
File "/home/runner/workspace/.pythonlibs/lib/python3.11/site-packages/sqlalchemy/orm/context.py", line 305, in orm_execute_statement
result = conn.execute(
         
File "/home/runner/workspace/.pythonlibs/lib/python3.11/site-packages/sqlalchemy/engine/base.py", line 1418, in execute
return meth(
       
File "/home/runner/workspace/.pythonlibs/lib/python3.11/site-packages/sqlalchemy/sql/elements.py", line 515, in _execute_on_connection
return connection._execute_clauseelement(
       
File "/home/runner/workspace/.pythonlibs/lib/python3.11/site-packages/sqlalchemy/engine/base.py", line 1640, in _execute_clauseelement
ret = self._execute_context(
      
File "/home/runner/workspace/.pythonlibs/lib/python3.11/site-packages/sqlalchemy/engine/base.py", line 1846, in _execute_context
return self._exec_single_context(
       
File "/home/runner/workspace/.pythonlibs/lib/python3.11/site-packages/sqlalchemy/engine/base.py", line 1986, in _exec_single_context
self._handle_dbapi_exception(
^
File "/home/runner/workspace/.pythonlibs/lib/python3.11/site-packages/sqlalchemy/engine/base.py", line 2355, in _handle_dbapi_exception
raise sqlalchemy_exception.with_traceback(exc_info[2]) from e
^^^^^^^^^^^^^^^^^^^^^^^^^^^^^^^^^^^^^^^^^^^^^^^^^^^^^^^^^^^^^
File "/home/runner/workspace/.pythonlibs/lib/python3.11/site-packages/sqlalchemy/engine/base.py", line 1967, in _exec_single_context
self.dialect.do_execute(
^
File "/home/runner/workspace/.pythonlibs/lib/python3.11/site-packages/sqlalchemy/engine/default.py", line 941, in do_execute
cursor.execute(statement, parameters)
^^^^^^^^^^^^^^^^^^^^^^^^^^^^^^^^^^^^^
sqlalchemy.exc.ProgrammingError: (psycopg2.errors.UndefinedColumn) column users.username does not exist
LINE 1: ...users.id AS users_id, users.email AS users_email, users.user...
^

[SQL: SELECT users.id AS users_id, users.email AS users_email, users.username AS users_username, users.encrypted_password AS users_encrypted_password, users.first_name AS users_first_name, users.last_name AS users_last_name, users.time_zone AS users_time_zone, users.created_at AS users_created_at, users.updated_at AS users_updated_at
FROM users
WHERE users.email = %(email_1)s OR users.username IS NOT NULL AND users.username = %(username_1)s
LIMIT %(param_1)s]
[parameters: {'email_1': 'phoebezcole@gmail.com', 'username_1': 'phoebezcole@gmail.com', 'param_1': 1}]
(Background on this error at: https://sqlalche.me/e/20/f405)