 <Rule '/' (HEAD, GET, OPTIONS) -> root>])
/home/runner/workspace/migrate_encrypted_passwords.py:33: LegacyAPIWarning: The Query.get() method is considered legacy as of the 1.x series of SQLAlchemy and becomes a legacy construct in 2.0. The method is now available as Session.get() (deprecated since: 2.0) (Background on SQLAlchemy 2.0 at: https://sqlalche.me/e/b8d9)
  user = User.query.get(user_id)
2025-03-08 23:17:30,702 - __main__ - INFO - Migrating password for user 1 (phoebezcole@gmail.com)
2025-03-08 23:17:30,702 - __main__ - WARNING - Password for user 1 is too long (162 chars)
2025-03-08 23:17:30,795 - __main__ - INFO - Created new hash for user 1 to fit in field
2025-03-08 23:17:30,795 - __main__ - INFO - Migrating password for user 3 (stellanovacole@gmail.com)
2025-03-08 23:17:30,795 - __main__ - WARNING - Password for user 3 is too long (162 chars)
2025-03-08 23:17:30,884 - __main__ - INFO - Created new hash for user 3 to fit in field
2025-03-08 23:17:30,884 - __main__ - INFO - Migrating password for user 4 (felixtiptoncole@gmail.com)
2025-03-08 23:17:30,884 - __main__ - WARNING - Password for user 4 is too long (162 chars)
2025-03-08 23:17:30,977 - __main__ - INFO - Created new hash for user 4 to fit in field
2025-03-08 23:17:30,977 - __main__ - INFO - Migrating password for user 5 (emily.juergens@gmail.com)
2025-03-08 23:17:30,977 - __main__ - WARNING - Password for user 5 is too long (162 chars)
2025-03-08 23:17:31,078 - __main__ - INFO - Created new hash for user 5 to fit in field
2025-03-08 23:17:31,078 - __main__ - INFO - Migrating password for user 6 (orion.bull@icloud.com)
2025-03-08 23:17:31,078 - __main__ - WARNING - Password for user 6 is too long (162 chars)
2025-03-08 23:17:31,184 - __main__ - INFO - Created new hash for user 6 to fit in field
2025-03-08 23:17:31,184 - __main__ - INFO - Migrating password for user 7 (macy.bull12@gmail.com)
2025-03-08 23:17:31,184 - __main__ - WARNING - Password for user 7 is too long (162 chars)
2025-03-08 23:17:31,281 - __main__ - INFO - Created new hash for user 7 to fit in field
2025-03-08 23:17:31,282 - __main__ - INFO - Migrating password for user 8 (saeus.bull@yahoo.com)
2025-03-08 23:17:31,282 - __main__ - WARNING - Password for user 8 is too long (162 chars)
2025-03-08 23:17:31,373 - __main__ - INFO - Created new hash for user 8 to fit in field
2025-03-08 23:17:31,374 - __main__ - INFO - Migrating password for user 9 (entertainment)
2025-03-08 23:17:31,374 - __main__ - WARNING - Password for user 9 is too long (162 chars)
2025-03-08 23:17:31,465 - __main__ - INFO - Created new hash for user 9 to fit in field
2025-03-08 23:17:31,465 - __main__ - INFO - Migrating password for user 2 (sallycole@gmail.com)
2025-03-08 23:17:31,465 - __main__ - WARNING - Password for user 2 is too long (162 chars)
2025-03-08 23:17:31,556 - __main__ - INFO - Created new hash for user 2 to fit in field
2025-03-08 23:17:31,556 - __main__ - INFO - Migrating password for user 10 (AyresAveryAcademy)
2025-03-08 23:17:31,556 - __main__ - WARNING - Password for user 10 is too long (162 chars)
2025-03-08 23:17:31,643 - __main__ - INFO - Created new hash for user 10 to fit in field
2025-03-08 23:17:31,643 - __main__ - INFO - Migrating password for user 11 (Heidi)
2025-03-08 23:17:31,643 - __main__ - WARNING - Password for user 11 is too long (162 chars)
2025-03-08 23:17:31,727 - __main__ - INFO - Created new hash for user 11 to fit in field
2025-03-08 23:17:31,727 - __main__ - INFO - Migrating password for user 12 (lkhaver@gmail.com)
2025-03-08 23:17:31,727 - __main__ - WARNING - Password for user 12 is too long (162 chars)
2025-03-08 23:17:31,812 - __main__ - INFO - Created new hash for user 12 to fit in field
Traceback (most recent call last):
  File "/home/runner/workspace/.pythonlibs/lib/python3.11/site-packages/sqlalchemy/engine/base.py", line 1936, in _exec_single_context
    self.dialect.do_executemany(
  File "/home/runner/workspace/.pythonlibs/lib/python3.11/site-packages/sqlalchemy/dialects/postgresql/psycopg2.py", line 794, in do_executemany
    cursor.executemany(statement, parameters)
psycopg2.errors.StringDataRightTruncation: value too long for type character varying(128)


The above exception was the direct cause of the following exception:

Traceback (most recent call last):
  File "/home/runner/workspace/migrate_encrypted_passwords.py", line 66, in <module>
    migrate_encrypted_passwords()
  File "/home/runner/workspace/migrate_encrypted_passwords.py", line 58, in migrate_encrypted_passwords
    db.session.commit()
  File "/home/runner/workspace/.pythonlibs/lib/python3.11/site-packages/sqlalchemy/orm/scoping.py", line 597, in commit
    return self._proxied.commit()
           ^^^^^^^^^^^^^^^^^^^^^^
  File "/home/runner/workspace/.pythonlibs/lib/python3.11/site-packages/sqlalchemy/orm/session.py", line 2028, in commit
    trans.commit(_to_root=True)
  File "<string>", line 2, in commit
  File "/home/runner/workspace/.pythonlibs/lib/python3.11/site-packages/sqlalchemy/orm/state_changes.py", line 139, in _go
    ret_value = fn(self, *arg, **kw)
                ^^^^^^^^^^^^^^^^^^^^
  File "/home/runner/workspace/.pythonlibs/lib/python3.11/site-packages/sqlalchemy/orm/session.py", line 1313, in commit
    self._prepare_impl()
  File "<string>", line 2, in _prepare_impl
  File "/home/runner/workspace/.pythonlibs/lib/python3.11/site-packages/sqlalchemy/orm/state_changes.py", line 139, in _go
    ret_value = fn(self, *arg, **kw)
                ^^^^^^^^^^^^^^^^^^^^
  File "/home/runner/workspace/.pythonlibs/lib/python3.11/site-packages/sqlalchemy/orm/session.py", line 1288, in _prepare_impl
    self.session.flush()
  File "/home/runner/workspace/.pythonlibs/lib/python3.11/site-packages/sqlalchemy/orm/session.py", line 4352, in flush
    self._flush(objects)
  File "/home/runner/workspace/.pythonlibs/lib/python3.11/site-packages/sqlalchemy/orm/session.py", line 4487, in _flush
    with util.safe_reraise():
  File "/home/runner/workspace/.pythonlibs/lib/python3.11/site-packages/sqlalchemy/util/langhelpers.py", line 146, in __exit__
    raise exc_value.with_traceback(exc_tb)
  File "/home/runner/workspace/.pythonlibs/lib/python3.11/site-packages/sqlalchemy/orm/session.py", line 4448, in _flush
    flush_context.execute()
  File "/home/runner/workspace/.pythonlibs/lib/python3.11/site-packages/sqlalchemy/orm/unitofwork.py", line 466, in execute
    rec.execute(self)
  File "/home/runner/workspace/.pythonlibs/lib/python3.11/site-packages/sqlalchemy/orm/unitofwork.py", line 642, in execute
    util.preloaded.orm_persistence.save_obj(
  File "/home/runner/workspace/.pythonlibs/lib/python3.11/site-packages/sqlalchemy/orm/persistence.py", line 85, in save_obj
    _emit_update_statements(
  File "/home/runner/workspace/.pythonlibs/lib/python3.11/site-packages/sqlalchemy/orm/persistence.py", line 912, in _emit_update_statements
    c = connection.execute(
        ^^^^^^^^^^^^^^^^^^^
  File "/home/runner/workspace/.pythonlibs/lib/python3.11/site-packages/sqlalchemy/engine/base.py", line 1418, in execute
    return meth(
           ^^^^^
  File "/home/runner/workspace/.pythonlibs/lib/python3.11/site-packages/sqlalchemy/sql/elements.py", line 515, in _execute_on_connection
    return connection._execute_clauseelement(
           ^^^^^^^^^^^^^^^^^^^^^^^^^^^^^^^^^^
  File "/home/runner/workspace/.pythonlibs/lib/python3.11/site-packages/sqlalchemy/engine/base.py", line 1640, in _execute_clauseelement
    ret = self._execute_context(
          ^^^^^^^^^^^^^^^^^^^^^^
  File "/home/runner/workspace/.pythonlibs/lib/python3.11/site-packages/sqlalchemy/engine/base.py", line 1846, in _execute_context
    return self._exec_single_context(
           ^^^^^^^^^^^^^^^^^^^^^^^^^^
  File "/home/runner/workspace/.pythonlibs/lib/python3.11/site-packages/sqlalchemy/engine/base.py", line 1986, in _exec_single_context
    self._handle_dbapi_exception(
  File "/home/runner/workspace/.pythonlibs/lib/python3.11/site-packages/sqlalchemy/engine/base.py", line 2355, in _handle_dbapi_exception
    raise sqlalchemy_exception.with_traceback(exc_info[2]) from e
  File "/home/runner/workspace/.pythonlibs/lib/python3.11/site-packages/sqlalchemy/engine/base.py", line 1936, in _exec_single_context
    self.dialect.do_executemany(
  File "/home/runner/workspace/.pythonlibs/lib/python3.11/site-packages/sqlalchemy/dialects/postgresql/psycopg2.py", line 794, in do_executemany
    cursor.executemany(statement, parameters)
sqlalchemy.exc.DataError: (psycopg2.errors.StringDataRightTruncation) value too long for type character varying(128)

[SQL: UPDATE users SET password_hash=%(password_hash)s WHERE users.id = %(users_id)s]
[parameters: [{'password_hash': 'scrypt:32768:8:1$9zOAIUJ70kQxu3LQ$ec31563f3f1bec56d60774a2c898c543c01376300d5d233c5489b3a1bf4994961b8793b9ac57b0af3b80e5f7eabd746c4a7c45caec167dae40185e93a14aae4f', 'users_id': 1}, {'password_hash': 'scrypt:32768:8:1$ZXiEX9xWgxykpBoC$9067420c704766e9f4893754f75aa5af873fd6d7b9311f9e9c9171d344ed0cc872691e905f5727954b1f5890037da70a101d62ae4a63324c4d6d061cb66ed682', 'users_id': 2}, {'password_hash': 'scrypt:32768:8:1$430JBlm3OS6ibm6F$2650be11d43a69af593dfaa8eb400239a97a104d17c87cddba1044a7c8218a9b2f26ea794286169eab17f6b5e5bfcca1fbb1fcf02372d192e655bb191a0acca4', 'users_id': 3}, {'password_hash': 'scrypt:32768:8:1$OQXOi2xLqiXSJQgx$f463cfbfa467965cc0af786b4ea1f731cab9b9d60e81e9d6e7dfe621b79bffa768216c8d2c88cdc2cd6a069d0dfb821d96dab9cd79cf394fa7ff65ef0c142857', 'users_id': 4}, {'password_hash': 'scrypt:32768:8:1$dA5c17YCQqMVJY1j$1e706314f52279c497431b72e8ff0f1b2523f2c1ce0f3901ee5c2e1e20a4bf9cd87ad106914f09e1f60f59900c87ac3e3833769c20639fe785fdd0c3bea952ae', 'users_id': 5}, {'password_hash': 'scrypt:32768:8:1$OPS3rnNaeB7aXTx9$60d1c8a353a57da1536a592bc59844fe130746282f04d06cad18a7e0122f524af86679123e609db1a33457f14d7579845cf512bc6cef73aa1404978e339bdfd2', 'users_id': 6}, {'password_hash': 'scrypt:32768:8:1$WYbpoPsfaJTVclAK$87e4c3f236caa42b3e48c8b7c3e7dbeeaf135e93ebfe43d4db7be4e3f60af79cb6807a9e26da7c4a6a81205402c1c5410724f490a9cc940a07bcb4a21be013a4', 'users_id': 7}, {'password_hash': 'scrypt:32768:8:1$GZJKwRwf0QzHu0Ie$e9431222425589bdba8a7def680bd0c04685e483582bc5506d18a988d912e383156ecc9f88f8b5a412e5360170a2f5cb8b4408e3942309b6ee6dd708f155fd04', 'users_id': 8}  ... displaying 10 of 12 total bound parameter sets ...  {'password_hash': 'scrypt:32768:8:1$d0DQO0CLcnnOugEX$abc9a56115732bb9da6fce0937779833d807d84d84199b417c8da0146548a6c2a5a1dcb76ebbee325fb267cb57836bc3670a6b1dbeadf3dbfef5ba907106b3aa', 'users_id': 11}, {'password_hash': 'scrypt:32768:8:1$aECbdIU4kA55fSGE$c07b5a10f9a220e66243a8b50205a24ff642c2f083795b7cd48956532bc56e980a6babd60e183df6c02cdc710a55219c36a985fb54e2f3900d968ec692324529', 'users_id': 12}]]
(Background on this error at: https://sqlalche.me/e/20/9h9h)