InvalidRequestError

sqlalchemy.exc.InvalidRequestError: Query.select_from() being called on a Query with existing criterion. 
Traceback (most recent call last)

    File "/home/runner/workspace/.pythonlibs/lib/python3.11/site-packages/flask/app.py", line 1514, in wsgi_app

    response = self.handle_exception(e)
               ^^^^^^^^^^^^^^^^^^^^^^^^

    File "/home/runner/workspace/.pythonlibs/lib/python3.11/site-packages/flask/app.py", line 1511, in wsgi_app

    response = self.full_dispatch_request()
               ^^^^^^^^^^^^^^^^^^^^^^^^^^^^

    File "/home/runner/workspace/.pythonlibs/lib/python3.11/site-packages/flask/app.py", line 919, in full_dispatch_request

    rv = self.handle_user_exception(e)
         ^^^^^^^^^^^^^^^^^^^^^^^^^^^^^

    File "/home/runner/workspace/.pythonlibs/lib/python3.11/site-packages/flask/app.py", line 917, in full_dispatch_request

    rv = self.dispatch_request()
         ^^^^^^^^^^^^^^^^^^^^^^^

    File "/home/runner/workspace/.pythonlibs/lib/python3.11/site-packages/flask/app.py", line 902, in dispatch_request

    return self.ensure_sync(self.view_functions[rule.endpoint])(**view_args)  # type: ignore[no-any-return]
           ^^^^^^^^^^^^^^^^^^^^^^^^^^^^^^^^^^^^^^^^^^^^^^^^^^^^^^^^^^^^^^^^^

    File "/home/runner/workspace/.pythonlibs/lib/python3.11/site-packages/flask_login/utils.py", line 290, in decorated_view

    return current_app.ensure_sync(func)(*args, **kwargs)
           ^^^^^^^^^^^^^^^^^^^^^^^^^^^^^^^^^^^^^^^^^^^^^^

    File "/home/runner/workspace/routes.py", line 630, in index

    .select_from(Task)
     ^^^^^^^^^^^^^^^^^

    File "<string>", line 2, in select_from
    File "/home/runner/workspace/.pythonlibs/lib/python3.11/site-packages/sqlalchemy/sql/base.py", line 279, in _generative

    x = fn(self, *args, **kw)
        ^^^^^^^^^^^^^^^^^^^^^

    File "<string>", line 2, in select_from
    File "/home/runner/workspace/.pythonlibs/lib/python3.11/site-packages/sqlalchemy/orm/base.py", line 305, in generate

    assertion(self, fn.__name__)
    ^^^^^^^^^^^^^^^^^^^^^^^^^^^^

    File "/home/runner/workspace/.pythonlibs/lib/python3.11/site-packages/sqlalchemy/orm/query.py", line 424, in _no_clauseelement_condition

    self._no_criterion_condition(meth)
    ^^^^^^^^^^^^^^^^^^^^^^^^^^^^^^^^^^

    File "/home/runner/workspace/.pythonlibs/lib/python3.11/site-packages/sqlalchemy/orm/query.py", line 406, in _no_criterion_condition

    self._no_criterion_assertion(meth, order_by, distinct)
    ^^^^^^^^^^^^^^^^^^^^^^^^^^^^^^^^^^^^^^^^^^^^^^^^^^^^^^

    File "/home/runner/workspace/.pythonlibs/lib/python3.11/site-packages/sqlalchemy/orm/query.py", line 398, in _no_criterion_assertion

    raise sa_exc.InvalidRequestError(
    ^

    sqlalchemy.exc.InvalidRequestError: Query.select_from() being called on a Query with existing criterion. 

The debugger caught an exception in your WSGI application. You can now look at the traceback which led to the error.

To switch between the interactive traceback and the plaintext one, you can click on the "Traceback" headline. From the text traceback you can also create a paste of it.
